<?xml version="1.0"?>
<robot xmlns:xacro="http://www.ros.org/wiki/xacro" >

    <xacro:include filename="inertial_macros.xacro"/>
	<xacro:include filename="$(find pioneer3dx_description)/urdf/robot_wheel.xacro" />

    <material name="white">
        <color rgba="1 1 1 1" />
    </material>

    <material name="white2">
        <color rgba="1 1 1 0.8" />
    </material>

    <material name="grey">
        <color rgba="0.7 0.7 0.7 1" />
    </material>

    <material name="orange">
        <color rgba="1 0.3 0.1 1"/>
    </material>

    <material name="blue">
        <color rgba="0.2 0.2 1 1"/>
    </material>

    <material name="black">
        <color rgba="0 0 0 1"/>
    </material>

    <material name="red">
        <color rgba="1 0.2 0.2 1" />
    </material>

    <material name="ChassisRed">
		<color rgba="0.851 0.0 0.0 1.0"/>
	</material>

	<material name="SonarYellow">
		<color rgba="0.715 0.583 0.210 1.0"/>
	</material>

	<material name="WheelBlack">
		<color rgba="0.117 0.117 0.117 1.0"/>
	</material>

	<material name="HubcapYellow">
		<color rgba="1.0 0.811 0.151 1.0"/>
	</material>

	<material name="TopBlack">
		<color rgba="0.038 0.038 0.038 1.0"/>
	</material>



	<!-- chassis -->
	<link name="base_link">
		<inertial>
			<mass value="3.5" />
			<!-- <origin xyz="-0.025 0 -0.223" /> -->
			<origin xyz="-0.05 0 0" />
			<inertia ixx="1" ixy="0" ixz="0" iyy="1" iyz="0" izz="1" />
		</inertial>

		<visual name="base_link">
			<origin xyz="-0.045 0 0.148" rpy="0 0 0" />
			<geometry name="pioneer_geom">
				<mesh filename="file://$(find pioneer3dx_description)/meshes/chassis.stl" />
			</geometry>
			<material name="ChassisRed">
				<color rgba="0.851 0.0 0.0 1.0" />
			</material>
		</visual>

		<collision>
			<origin xyz="-0.045 0 0.145" rpy="0 0 0" />
			<geometry>
				<box size="0.35 0.25 0.14" />
			</geometry>
		</collision>
	</link>
    
    <!-- base footprint link -->

    <joint name="base_footprint_joint" type="fixed">
        <parent link="base_link"/>
        <child link="base_footprint"/>
        <origin xyz="0 0 0" rpy="0 0 0"/>
    </joint>

    <link name="base_footprint">
    </link>

	<!-- top_plate -->
	<link name="top_plate">
		<inertial>
			<mass value="0.01" />
			<origin xyz="0 0 0" />
			<inertia ixx="1" ixy="0" ixz="0" iyy="1" iyz="0" izz="1" />
		</inertial>

		<visual name="base_visual">
			<origin xyz="0 0 0" rpy="0 0 0" />
			<geometry name="top_geom">
				<mesh filename="file://$(find pioneer3dx_description)/meshes/top.stl" />
			</geometry>

			<material name="TopBlack">
				<color rgba="0.038 0.038 0.038 1.0" />
			</material>
		</visual>

		<collision>
			<origin xyz="0.0 0 0" rpy="0 0 0" />
			<geometry name="pioneer_geom">
				<box size="0.45 0.38 0.01" />
			</geometry>
		</collision>
	</link>

	<joint name="base_top_joint" type="fixed">
		<origin xyz="-0.045 0 0.234" rpy="0 0 0" />
		<parent link="base_link" />
		<child link="top_plate" />
	</joint>

	<!-- swivel -->
	<link name="swivel">
		<inertial>
			<mass value="0.1" />
			<origin xyz="0 0 0" />
			<inertia ixx="0.01" ixy="0" ixz="0" iyy="0.01" iyz="0" izz="0.01" />
		</inertial>

		<visual name="base_visual">
			<origin xyz="0 0 0" rpy="0 0 0" />
			<geometry name="pioneer_geom">
				<mesh filename="file://$(find pioneer3dx_description)/meshes/swivel.stl" />
			</geometry>
			<material name="swivel">
				<color rgba="0.5 0.5 0.5 1" />
			</material>
		</visual>

		<collision>
			<origin xyz="0 0 0" rpy="0 0 0" />
			<geometry>
				<box size="0.01 0.01 0.01" />
			</geometry>
		</collision>
	</link>

	<joint name="base_swivel_joint" type="fixed">
		<origin xyz="-0.185 0 0.055" rpy="0 0 0" />
		<axis xyz="0 0 1" />
		<anchor xyz="0 0 0" />
		<limit effort="100" velocity="100" k_velocity="0" />
		<joint_properties damping="0.0" friction="0.0" />
		<parent link="base_link" />
		<child link="swivel" />
	</joint>

	<!-- center_hubcap -->
	<link name="center_hubcap">
		<inertial>
			<mass value="0.01" />
			<origin xyz="0 0 0" />
			<inertia ixx="0.012411765597" ixy="-0.000711733678" ixz="0.00050272983"
				iyy="0.015218160428" iyz="-0.000004273467" izz="0.011763977943" />
		</inertial>

		<visual name="base_visual">
			<origin xyz="0 0 0" rpy="0 0 0" />
			<geometry name="pioneer_geom">
				<mesh filename="file://$(find pioneer3dx_description)/meshes/center_hubcap.stl" />
			</geometry>
			<material name="swivel">
				<color rgba="0.5 0.5 0.5 1" />
			</material>
		</visual>

		<collision>
			<origin xyz="0 0 0" rpy="0 0 0" />
			<geometry>
				<box size="0.01 0.01 0.01" />
			</geometry>
		</collision>
	</link>

	<joint name="swivel_hubcap_joint" type="continuous">
		<origin xyz="-0.026 0 -0.016" rpy="0 0 0" />
		<axis xyz="0 1 0" />
		<anchor xyz="0 0 0" />
		<limit effort="100" velocity="100" k_velocity="0" />
		<joint_properties damping="0.0" friction="0.0" />
		<parent link="swivel" />
		<child link="center_hubcap" />
	</joint>

	<!-- center_wheel -->
	<link name="center_wheel">
		<inertial>
			<mass value="0.1" />
			<origin xyz="0 0 0" />
			<inertia ixx="0.012411765597" ixy="-0.000711733678" ixz="0.00050272983"
				iyy="0.015218160428" iyz="-0.000004273467" izz="0.011763977943" />
		</inertial>

		<visual name="base_visual">
			<origin xyz="0 0 0" rpy="0 0 0" />
			<geometry name="pioneer_geom">
				<mesh filename="file://$(find pioneer3dx_description)/meshes/center_wheel.stl" />
			</geometry>
			<material name="WheelBlack">
				<color rgba="0.117 0.117 0.117 1" />
			</material>
		</visual>

		<collision>
			<origin xyz="0 0 0" rpy="${-3.1415927/2.0} 0 0" />
			<geometry>
				<cylinder radius="0.0375" length="0.01" />
			</geometry>
		</collision>
	</link>

	<joint name="center_wheel_joint" type="fixed">
		<origin xyz="-0.0035 0 -0.001" rpy="0 0 0" />
		<parent link="center_hubcap" />
		<child link="center_wheel" />
	</joint>

	<!-- rodas principais -->
	<xacro:p3dx_wheel 
		suffix="left" 
		parent="base_link" 
		reflect="1.0"/>

	<xacro:p3dx_wheel 
		suffix="right" 
		parent="base_link" 
		reflect="-1.0"/>

	<!-- front_sonar -->
	<link name="front_sonar">
		<inertial>
			<mass value="0.0001" />
			<origin xyz="0 0 0" />
			<inertia ixx="1" ixy="0" ixz="0" iyy="1" iyz="0" izz="1" />
		</inertial>

		<visual name="front_sonar_vis">
			<origin rpy="0 0 0" xyz="0 0 0" />
			<geometry name="pioneer_geom">
				<mesh filename="file://$(find pioneer3dx_description)/meshes/front_sonar.stl" />
			</geometry>
			<material name="SonarYellow">
				<color rgba="0.715 0.583 0.210 1.0" />
			</material>
		</visual>

		<collision>
			<origin rpy="0 0 0" xyz="0 0 0" />
			<geometry>
				<box size="0.01 0.01 0.01" />
			</geometry>
		</collision>
	</link>

	<joint name="base_front_joint" type="fixed">
		<origin rpy="0 0 0" xyz="0.109 0 0.209" />
		<parent link="base_link" />
		<child link="front_sonar" />
	</joint>


    
    
</robot>