<?xml version="1.0" ?>
<!-- =================================================================================== -->
<!-- |    This document was autogenerated by xacro from robot.urdf.xacro               | -->
<!-- |    EDITING THIS FILE BY HAND IS NOT RECOMMENDED                                 | -->
<!-- =================================================================================== -->
<robot name="robot">
  <!-- Specify some standard inertial calculations https://en.wikipedia.org/wiki/List_of_moments_of_inertia -->
  <!-- These make use of xacro's mathematical functionality -->
  <material name="white">
    <color rgba="1 1 1 1"/>
  </material>
  <material name="white2">
    <color rgba="1 1 1 0.8"/>
  </material>
  <material name="grey">
    <color rgba="0.7 0.7 0.7 1"/>
  </material>
  <material name="orange">
    <color rgba="1 0.3 0.1 1"/>
  </material>
  <material name="blue">
    <color rgba="0.2 0.2 1 1"/>
  </material>
  <material name="black">
    <color rgba="0 0 0 1"/>
  </material>
  <material name="red">
    <color rgba="1 0.2 0.2 1"/>
  </material>
  <!-- BASE LINK -->
  <link name="base_link">

    </link>
  <!-- CHASSIS LINK -->
  <joint name="chassis_joint" type="fixed">
    <parent link="base_link"/>
    <child link="chassis"/>
    <origin xyz="0.0 0 -0.017"/>
  </joint>
  <link name="chassis">
    <visual>
      <origin xyz="0.0 0 0.002"/>
      <geometry>
        <cylinder length="0.02" radius="0.105"/>
      </geometry>
      <material name="white"/>
    </visual>
    <visual>
      <origin xyz="0.0 0 0.072"/>
      <geometry>
        <cylinder length="0.005" radius="0.105"/>
      </geometry>
      <material name="white"/>
    </visual>
    <visual>
      <origin xyz="0.0 0 0.145"/>
      <geometry>
        <cylinder length="0.005" radius="0.105"/>
      </geometry>
      <material name="white"/>
    </visual>
    <visual>
      <origin xyz="0.0 0 0.145"/>
      <geometry>
        <cylinder length="0.005" radius="0.105"/>
      </geometry>
      <material name="white"/>
    </visual>
    <visual>
      <origin xyz="0.05 0.05 0.067"/>
      <geometry>
        <cylinder length="0.15" radius="0.005"/>
      </geometry>
      <material name="grey"/>
    </visual>
    <visual>
      <origin xyz="-0.05 0.05 0.067"/>
      <geometry>
        <cylinder length="0.15" radius="0.005"/>
      </geometry>
      <material name="grey"/>
    </visual>
    <visual>
      <origin xyz="-0.05 -0.05 0.067"/>
      <geometry>
        <cylinder length="0.15" radius="0.005"/>
      </geometry>
      <material name="grey"/>
    </visual>
    <visual>
      <origin xyz="0.05 -0.05 0.067"/>
      <geometry>
        <cylinder length="0.15" radius="0.005"/>
      </geometry>
      <material name="grey"/>
    </visual>
    <collision>
      <origin xyz="0.0 0 0.067"/>
      <geometry>
        <cylinder length="0.15" radius="0.11"/>
      </geometry>
    </collision>
    <inertial>
      <origin rpy="0 0 0" xyz="0 0 0.002"/>
      <mass value="2"/>
      <inertia ixx="0.005579166666666666" ixy="0.0" ixz="0.0" iyy="0.005579166666666666" iyz="0.0" izz="0.011024999999999998"/>
    </inertial>
  </link>
  <!-- LEFT WHEEL LINK -->
  <joint name="left_wheel_joint" type="continuous">
    <parent link="base_link"/>
    <child link="left_wheel"/>
    <origin rpy="-1.57 0 0" xyz="0 0.087 0"/>
    <axis xyz="0 0 1"/>
  </joint>
  <link name="left_wheel">
    <visual>
      <geometry>
        <cylinder length="0.025" radius="0.03"/>
      </geometry>
      <material name="black"/>
    </visual>
    <collision>
      <geometry>
        <cylinder length="0.025" radius="0.03"/>
      </geometry>
    </collision>
    <inertial>
      <origin rpy="0 0 0" xyz="0 0 0"/>
      <mass value="0.1"/>
      <inertia ixx="2.3125000000000003e-05" ixy="0.0" ixz="0.0" iyy="2.3125000000000003e-05" iyz="0.0" izz="3.125000000000001e-05"/>
    </inertial>
  </link>
  <gazebo reference="left_wheel">
    <material>Gazebo/Black</material>
  </gazebo>
  <!-- RIGHT WHEEL LINK -->
  <joint name="right_wheel_joint" type="continuous">
    <parent link="base_link"/>
    <child link="right_wheel"/>
    <origin rpy="1.57 0 0" xyz="0 -0.087 0"/>
    <axis xyz="0 0 -1"/>
  </joint>
  <link name="right_wheel">
    <visual>
      <geometry>
        <cylinder length="0.025" radius="0.03"/>
      </geometry>
      <material name="black"/>
    </visual>
    <collision>
      <geometry>
        <cylinder length="0.025" radius="0.03"/>
      </geometry>
    </collision>
    <inertial>
      <origin rpy="0 0 0" xyz="0 0 0"/>
      <mass value="0.1"/>
      <inertia ixx="2.3125000000000003e-05" ixy="0.0" ixz="0.0" iyy="2.3125000000000003e-05" iyz="0.0" izz="3.125000000000001e-05"/>
    </inertial>
  </link>
  <!-- support front-->
  <joint name="suport_front_joint" type="fixed">
    <parent link="chassis"/>
    <child link="suppor_front"/>
    <origin xyz="0.0825 0 -0.01"/>
  </joint>
  <link name="suppor_front">
    <visual>
      <geometry>
        <box size="0.03 0.075 0.005"/>
      </geometry>
      <material name="white"/>
    </visual>
    <collision>
      <geometry>
        <box size="0.03 0.075 0.005"/>
      </geometry>
    </collision>
    <inertial>
      <origin rpy="0 0 0" xyz="0.0 0 0.0"/>
      <mass value="0.01"/>
      <inertia ixx="4.708333333333333e-06" ixy="0.0" ixz="0.0" iyy="7.708333333333332e-07" iyz="0.0" izz="5.437499999999999e-06"/>
    </inertial>
  </link>
  <!-- support back-->
  <joint name="suport_back_joint" type="fixed">
    <parent link="chassis"/>
    <child link="suppor_back"/>
    <origin xyz="-0.0825 0 -0.01"/>
  </joint>
  <link name="suppor_back">
    <visual>
      <geometry>
        <box size="0.03 0.075 0.005"/>
      </geometry>
      <material name="white"/>
    </visual>
    <collision>
      <geometry>
        <box size="0.03 0.075 0.005"/>
      </geometry>
    </collision>
    <inertial>
      <origin rpy="0 0 0" xyz="0.0 0 0.0"/>
      <mass value="0.01"/>
      <inertia ixx="4.708333333333333e-06" ixy="0.0" ixz="0.0" iyy="7.708333333333332e-07" iyz="0.0" izz="5.437499999999999e-06"/>
    </inertial>
  </link>
  <joint name="laser_joint" type="fixed">
    <parent link="chassis"/>
    <child link="laser_frame"/>
    <origin rpy="0 0 1.5707963267948966" xyz="0.0 0 0.165"/>
  </joint>
  <link name="laser_frame">
    <visual>
      <geometry>
        <cylinder length="0.04" radius="0.0325"/>
      </geometry>
      <material name="blue"/>
    </visual>
    <collision>
      <geometry>
        <cylinder length="0.04" radius="0.0325"/>
      </geometry>
    </collision>
    <inertial>
      <origin rpy="0 0 0" xyz="0 0 0"/>
      <mass value="0.05"/>
      <inertia ixx="1.986979166666667e-05" ixy="0.0" ixz="0.0" iyy="1.986979166666667e-05" iyz="0.0" izz="2.6406250000000005e-05"/>
    </inertial>
  </link>
  <joint name="imu_joint" type="fixed">
    <parent link="chassis"/>
    <child link="imu_frame"/>
    <origin rpy="0 0 1.5707963267948966" xyz="0.02 0.045 0.072"/>
  </joint>
  <link name="imu_frame">
    <visual>
      <geometry>
        <box size="0.02 0.02 0.0025"/>
      </geometry>
      <material name="blue"/>
    </visual>
    <collision>
      <geometry>
        <box size="0.02 0.02 0.0025"/>
      </geometry>
    </collision>
    <inertial>
      <origin rpy="0 0 0" xyz="0.0 0 0.0"/>
      <mass value="0.005"/>
      <inertia ixx="1.6927083333333334e-07" ixy="0.0" ixz="0.0" iyy="3.776041666666666e-07" iyz="0.0" izz="5.416666666666666e-07"/>
    </inertial>
  </link>
  <gazebo reference="chassis">
    <material>Gazebo/White</material>
  </gazebo>
  <gazebo reference="left_wheel">
    <material>Gazebo/Black</material>
  </gazebo>
  <gazebo reference="right_wheel">
    <material>Gazebo/Black</material>
  </gazebo>
  <gazebo reference="suppor_front">
    <material>Gazebo/White</material>
  </gazebo>
  <gazebo reference="suppor_back">
    <material>Gazebo/White</material>
  </gazebo>
  <gazebo reference="laser_frame">
    <material>Gazebo/Blue</material>
    <sensor name="laser" type="ray">
      <pose> 0 0 0 0 0 0 </pose>
      <visualize>true</visualize>
      <update_rate>10</update_rate>
      <ray>
        <scan>
          <horizontal>
            <samples>360</samples>
            <min_angle>-3.14</min_angle>
            <max_angle>3.14</max_angle>
          </horizontal>
        </scan>
        <range>
          <min>0.3</min>
          <max>12</max>
        </range>
      </ray>
      <plugin filename="libgazebo_ros_ray_sensor.so" name="laser_controller">
        <ros>
          <argument>~/out:=scan</argument>
        </ros>
        <output_type>sensor_msgs/LaserScan</output_type>
        <frame_name>laser_frame</frame_name>
      </plugin>
    </sensor>
  </gazebo>
  <gazebo>
    <plugin filename="libgazebo_ros_diff_drive.so" name="diff_drive">
      <!-- Wheel Information -->
      <left_joint>left_wheel_joint</left_joint>
      <right_joint>right_wheel_joint</right_joint>
      <wheel_separation>0.173</wheel_separation>
      <wheel_diameter>0.06</wheel_diameter>
      <!-- Limits -->
      <max_wheel_torque>200</max_wheel_torque>
      <max_wheel_acceleration>10.0</max_wheel_acceleration>
      <!-- Output -->
      <odometry_frame>odom</odometry_frame>
      <robot_base_frame>base_link</robot_base_frame>
      <publish_odom>true</publish_odom>
      <publish_odom_tf>true</publish_odom_tf>
      <publish_wheel_tf>true</publish_wheel_tf>
    </plugin>
  </gazebo>
</robot>
